Traceback (most recent call last):
  File "start_bot.py", line 44, in <module>
    fileHandler = logging.handlers.RotatingFileHandler(filename='/home/ubuntu/g2b_bot/log/start_bot.log', maxBytes=file_max_bytes, backupCount=10)
  File "/usr/lib/python3.8/logging/handlers.py", line 148, in __init__
    BaseRotatingHandler.__init__(self, filename, mode, encoding, delay)
  File "/usr/lib/python3.8/logging/handlers.py", line 55, in __init__
    logging.FileHandler.__init__(self, filename, mode, encoding, delay)
  File "/usr/lib/python3.8/logging/__init__.py", line 1143, in __init__
    StreamHandler.__init__(self, self._open())
  File "/usr/lib/python3.8/logging/__init__.py", line 1172, in _open
    return open(self.baseFilename, self.mode, encoding=self.encoding)
PermissionError: [Errno 13] Permission denied: '/home/ubuntu/g2b_bot/log/start_bot.log'
Error while getting Updates: Conflict: terminated by other getUpdates request; make sure that only one bot instance is running
No error handlers are registered, logging exception.
Traceback (most recent call last):
  File "/usr/local/lib/python3.8/dist-packages/telegram/ext/updater.py", line 465, in _network_loop_retry
    if not action_cb():
  File "/usr/local/lib/python3.8/dist-packages/telegram/ext/updater.py", line 416, in polling_action_cb
    updates = self.bot.get_updates(
  File "<decorator-gen-31>", line 2, in get_updates
  File "/usr/local/lib/python3.8/dist-packages/telegram/bot.py", line 135, in decorator
    result = func(*args, **kwargs)
  File "/usr/local/lib/python3.8/dist-packages/telegram/bot.py", line 2638, in get_updates
    result = self._post(
  File "/usr/local/lib/python3.8/dist-packages/telegram/bot.py", line 245, in _post
    return self.request.post(f'{self.base_url}/{endpoint}', data=data, timeout=timeout)
  File "/usr/local/lib/python3.8/dist-packages/telegram/utils/request.py", line 349, in post
    result = self._request_wrapper(
  File "/usr/local/lib/python3.8/dist-packages/telegram/utils/request.py", line 276, in _request_wrapper
    raise Conflict(message)
telegram.error.Conflict: Conflict: terminated by other getUpdates request; make sure that only one bot instance is running
Error while getting Updates: Conflict: terminated by other getUpdates request; make sure that only one bot instance is running
No error handlers are registered, logging exception.
Traceback (most recent call last):
  File "/usr/local/lib/python3.8/dist-packages/telegram/ext/updater.py", line 465, in _network_loop_retry
    if not action_cb():
  File "/usr/local/lib/python3.8/dist-packages/telegram/ext/updater.py", line 416, in polling_action_cb
    updates = self.bot.get_updates(
  File "<decorator-gen-31>", line 2, in get_updates
  File "/usr/local/lib/python3.8/dist-packages/telegram/bot.py", line 135, in decorator
    result = func(*args, **kwargs)
  File "/usr/local/lib/python3.8/dist-packages/telegram/bot.py", line 2638, in get_updates
    result = self._post(
  File "/usr/local/lib/python3.8/dist-packages/telegram/bot.py", line 245, in _post
    return self.request.post(f'{self.base_url}/{endpoint}', data=data, timeout=timeout)
  File "/usr/local/lib/python3.8/dist-packages/telegram/utils/request.py", line 349, in post
    result = self._request_wrapper(
  File "/usr/local/lib/python3.8/dist-packages/telegram/utils/request.py", line 276, in _request_wrapper
    raise Conflict(message)
telegram.error.Conflict: Conflict: terminated by other getUpdates request; make sure that only one bot instance is running
